{
  "cells": [
    {
      "cell_type": "code",
      "execution_count": null,
      "metadata": {
        "colab": {
          "base_uri": "https://localhost:8080/"
        },
        "id": "OgB5sbYemJSU",
        "outputId": "71d8e337-8cce-460d-f416-be05cfca9542"
      },
      "outputs": [
        {
          "name": "stdout",
          "output_type": "stream",
          "text": [
            "Collecting pycep-correios\n",
            "  Downloading pycep_correios-5.0.0-py2.py3-none-any.whl (7.1 kB)\n",
            "Requirement already satisfied: requests>=2.7.0 in /usr/local/lib/python3.7/dist-packages (from pycep-correios) (2.23.0)\n",
            "Collecting zeep>=2.0.0\n",
            "  Downloading zeep-4.1.0-py2.py3-none-any.whl (100 kB)\n",
            "\u001b[K     |████████████████████████████████| 100 kB 4.8 MB/s \n",
            "\u001b[?25hRequirement already satisfied: urllib3!=1.25.0,!=1.25.1,<1.26,>=1.21.1 in /usr/local/lib/python3.7/dist-packages (from requests>=2.7.0->pycep-correios) (1.24.3)\n",
            "Requirement already satisfied: idna<3,>=2.5 in /usr/local/lib/python3.7/dist-packages (from requests>=2.7.0->pycep-correios) (2.10)\n",
            "Requirement already satisfied: chardet<4,>=3.0.2 in /usr/local/lib/python3.7/dist-packages (from requests>=2.7.0->pycep-correios) (3.0.4)\n",
            "Requirement already satisfied: certifi>=2017.4.17 in /usr/local/lib/python3.7/dist-packages (from requests>=2.7.0->pycep-correios) (2021.10.8)\n",
            "Collecting lxml>=4.6.0\n",
            "  Downloading lxml-4.8.0-cp37-cp37m-manylinux_2_17_x86_64.manylinux2014_x86_64.manylinux_2_24_x86_64.whl (6.4 MB)\n",
            "\u001b[K     |████████████████████████████████| 6.4 MB 58.2 MB/s \n",
            "\u001b[?25hCollecting requests-toolbelt>=0.7.1\n",
            "  Downloading requests_toolbelt-0.9.1-py2.py3-none-any.whl (54 kB)\n",
            "\u001b[K     |████████████████████████████████| 54 kB 2.8 MB/s \n",
            "\u001b[?25hCollecting isodate>=0.5.4\n",
            "  Downloading isodate-0.6.1-py2.py3-none-any.whl (41 kB)\n",
            "\u001b[K     |████████████████████████████████| 41 kB 550 kB/s \n",
            "\u001b[?25hCollecting requests-file>=1.5.1\n",
            "  Downloading requests_file-1.5.1-py2.py3-none-any.whl (3.7 kB)\n",
            "Requirement already satisfied: cached-property>=1.3.0 in /usr/local/lib/python3.7/dist-packages (from zeep>=2.0.0->pycep-correios) (1.5.2)\n",
            "Requirement already satisfied: attrs>=17.2.0 in /usr/local/lib/python3.7/dist-packages (from zeep>=2.0.0->pycep-correios) (21.4.0)\n",
            "Collecting platformdirs>=1.4.0\n",
            "  Downloading platformdirs-2.5.2-py3-none-any.whl (14 kB)\n",
            "Requirement already satisfied: pytz in /usr/local/lib/python3.7/dist-packages (from zeep>=2.0.0->pycep-correios) (2022.1)\n",
            "Requirement already satisfied: six in /usr/local/lib/python3.7/dist-packages (from isodate>=0.5.4->zeep>=2.0.0->pycep-correios) (1.15.0)\n",
            "Installing collected packages: requests-toolbelt, requests-file, platformdirs, lxml, isodate, zeep, pycep-correios\n",
            "  Attempting uninstall: lxml\n",
            "    Found existing installation: lxml 4.2.6\n",
            "    Uninstalling lxml-4.2.6:\n",
            "      Successfully uninstalled lxml-4.2.6\n",
            "Successfully installed isodate-0.6.1 lxml-4.8.0 platformdirs-2.5.2 pycep-correios-5.0.0 requests-file-1.5.1 requests-toolbelt-0.9.1 zeep-4.1.0\n"
          ]
        }
      ],
      "source": [
        "pip install pycep-correios"
      ]
    },
    {
      "cell_type": "code",
      "execution_count": null,
      "metadata": {
        "colab": {
          "base_uri": "https://localhost:8080/"
        },
        "id": "UTxOapfJmnON",
        "outputId": "5c819546-2ce1-47a7-8bbb-f1428c59d12e"
      },
      "outputs": [
        {
          "output_type": "stream",
          "name": "stdout",
          "text": [
            "   UF   MUNICÍPIO        ESTABELECIMENTO                   LOGRADOURO NÚMERO  \\\n",
            "0  SP  ADAMANTINA      UBS NOVE DE JULHO            RUA NOVE DE JULHO    841   \n",
            "1  SP  ADAMANTINA             UBS DORIGO    R DEOLINDA FERREIRA SILVA    S/N   \n",
            "2  SP  ADAMANTINA        UBS VILA JARDIM       ALAMEDA DAS MARGARIDAS    S/N   \n",
            "3  SP  ADAMANTINA       UBS PARQUE CECAP  R PROF NOEMIA BUENO DO VALE    145   \n",
            "4  SP  ADAMANTINA  UBS JARDIM ADAMANTINA                 JOAO PERRONE    S/N   \n",
            "\n",
            "              BAIRRO                                       END_COMPLETO  \n",
            "0             CENTRO    RUA NOVE DE JULHO, 841,ADAMANTINA - SP - BRAZIL  \n",
            "1    ESTANCIA DORIGO  R DEOLINDA FERREIRA SILVA, ADAMANTINA - SP - B...  \n",
            "2        VILA JARDIM   ALAMEDA DAS MARGARIDAS, ADAMANTINA - SP - BRAZIL  \n",
            "3       PARQUE CECAP  R PROF NOEMIA BUENO DO VALE, 145,ADAMANTINA - ...  \n",
            "4  JARDIM ADAMANTINA             JOAO PERRONE, ADAMANTINA - SP - BRAZIL  \n"
          ]
        },
        {
          "output_type": "stream",
          "name": "stderr",
          "text": [
            "RateLimiter caught an error, retrying (0/2 tries). Called with (*('ESTRADA DO MORRO GRANDE, IBIUNA - SP - BRAZIL',), **{}).\n",
            "Traceback (most recent call last):\n",
            "  File \"/usr/local/lib/python3.7/dist-packages/geopy/geocoders/base.py\", line 344, in _call_geocoder\n",
            "    page = requester(req, timeout=timeout, **kwargs)\n",
            "  File \"/usr/lib/python3.7/urllib/request.py\", line 525, in open\n",
            "    response = self._open(req, data)\n",
            "  File \"/usr/lib/python3.7/urllib/request.py\", line 543, in _open\n",
            "    '_open', req)\n",
            "  File \"/usr/lib/python3.7/urllib/request.py\", line 503, in _call_chain\n",
            "    result = func(*args)\n",
            "  File \"/usr/lib/python3.7/urllib/request.py\", line 1393, in https_open\n",
            "    context=self._context, check_hostname=self._check_hostname)\n",
            "  File \"/usr/lib/python3.7/urllib/request.py\", line 1353, in do_open\n",
            "    r = h.getresponse()\n",
            "  File \"/usr/lib/python3.7/http/client.py\", line 1373, in getresponse\n",
            "    response.begin()\n",
            "  File \"/usr/lib/python3.7/http/client.py\", line 319, in begin\n",
            "    version, status, reason = self._read_status()\n",
            "  File \"/usr/lib/python3.7/http/client.py\", line 280, in _read_status\n",
            "    line = str(self.fp.readline(_MAXLINE + 1), \"iso-8859-1\")\n",
            "  File \"/usr/lib/python3.7/socket.py\", line 589, in readinto\n",
            "    return self._sock.recv_into(b)\n",
            "  File \"/usr/lib/python3.7/ssl.py\", line 1071, in recv_into\n",
            "    return self.read(nbytes, buffer)\n",
            "  File \"/usr/lib/python3.7/ssl.py\", line 929, in read\n",
            "    return self._sslobj.read(len, buffer)\n",
            "socket.timeout: The read operation timed out\n",
            "\n",
            "During handling of the above exception, another exception occurred:\n",
            "\n",
            "Traceback (most recent call last):\n",
            "  File \"/usr/local/lib/python3.7/dist-packages/geopy/extra/rate_limiter.py\", line 130, in __call__\n",
            "    return self.func(*args, **kwargs)\n",
            "  File \"/usr/local/lib/python3.7/dist-packages/geopy/geocoders/osm.py\", line 307, in geocode\n",
            "    self._call_geocoder(url, timeout=timeout), exactly_one\n",
            "  File \"/usr/local/lib/python3.7/dist-packages/geopy/geocoders/base.py\", line 371, in _call_geocoder\n",
            "    raise GeocoderTimedOut('Service timed out')\n",
            "geopy.exc.GeocoderTimedOut: Service timed out\n",
            "RateLimiter caught an error, retrying (0/2 tries). Called with (*('PERAMIRIM, 1,SAO PAULO - SP - BRAZIL',), **{}).\n",
            "Traceback (most recent call last):\n",
            "  File \"/usr/local/lib/python3.7/dist-packages/geopy/geocoders/base.py\", line 344, in _call_geocoder\n",
            "    page = requester(req, timeout=timeout, **kwargs)\n",
            "  File \"/usr/lib/python3.7/urllib/request.py\", line 525, in open\n",
            "    response = self._open(req, data)\n",
            "  File \"/usr/lib/python3.7/urllib/request.py\", line 543, in _open\n",
            "    '_open', req)\n",
            "  File \"/usr/lib/python3.7/urllib/request.py\", line 503, in _call_chain\n",
            "    result = func(*args)\n",
            "  File \"/usr/lib/python3.7/urllib/request.py\", line 1393, in https_open\n",
            "    context=self._context, check_hostname=self._check_hostname)\n",
            "  File \"/usr/lib/python3.7/urllib/request.py\", line 1353, in do_open\n",
            "    r = h.getresponse()\n",
            "  File \"/usr/lib/python3.7/http/client.py\", line 1373, in getresponse\n",
            "    response.begin()\n",
            "  File \"/usr/lib/python3.7/http/client.py\", line 319, in begin\n",
            "    version, status, reason = self._read_status()\n",
            "  File \"/usr/lib/python3.7/http/client.py\", line 280, in _read_status\n",
            "    line = str(self.fp.readline(_MAXLINE + 1), \"iso-8859-1\")\n",
            "  File \"/usr/lib/python3.7/socket.py\", line 589, in readinto\n",
            "    return self._sock.recv_into(b)\n",
            "  File \"/usr/lib/python3.7/ssl.py\", line 1071, in recv_into\n",
            "    return self.read(nbytes, buffer)\n",
            "  File \"/usr/lib/python3.7/ssl.py\", line 929, in read\n",
            "    return self._sslobj.read(len, buffer)\n",
            "socket.timeout: The read operation timed out\n",
            "\n",
            "During handling of the above exception, another exception occurred:\n",
            "\n",
            "Traceback (most recent call last):\n",
            "  File \"/usr/local/lib/python3.7/dist-packages/geopy/extra/rate_limiter.py\", line 130, in __call__\n",
            "    return self.func(*args, **kwargs)\n",
            "  File \"/usr/local/lib/python3.7/dist-packages/geopy/geocoders/osm.py\", line 307, in geocode\n",
            "    self._call_geocoder(url, timeout=timeout), exactly_one\n",
            "  File \"/usr/local/lib/python3.7/dist-packages/geopy/geocoders/base.py\", line 371, in _call_geocoder\n",
            "    raise GeocoderTimedOut('Service timed out')\n",
            "geopy.exc.GeocoderTimedOut: Service timed out\n",
            "RateLimiter caught an error, retrying (1/2 tries). Called with (*('PERAMIRIM, 1,SAO PAULO - SP - BRAZIL',), **{}).\n",
            "Traceback (most recent call last):\n",
            "  File \"/usr/local/lib/python3.7/dist-packages/geopy/geocoders/base.py\", line 344, in _call_geocoder\n",
            "    page = requester(req, timeout=timeout, **kwargs)\n",
            "  File \"/usr/lib/python3.7/urllib/request.py\", line 525, in open\n",
            "    response = self._open(req, data)\n",
            "  File \"/usr/lib/python3.7/urllib/request.py\", line 543, in _open\n",
            "    '_open', req)\n",
            "  File \"/usr/lib/python3.7/urllib/request.py\", line 503, in _call_chain\n",
            "    result = func(*args)\n",
            "  File \"/usr/lib/python3.7/urllib/request.py\", line 1393, in https_open\n",
            "    context=self._context, check_hostname=self._check_hostname)\n",
            "  File \"/usr/lib/python3.7/urllib/request.py\", line 1353, in do_open\n",
            "    r = h.getresponse()\n",
            "  File \"/usr/lib/python3.7/http/client.py\", line 1373, in getresponse\n",
            "    response.begin()\n",
            "  File \"/usr/lib/python3.7/http/client.py\", line 319, in begin\n",
            "    version, status, reason = self._read_status()\n",
            "  File \"/usr/lib/python3.7/http/client.py\", line 280, in _read_status\n",
            "    line = str(self.fp.readline(_MAXLINE + 1), \"iso-8859-1\")\n",
            "  File \"/usr/lib/python3.7/socket.py\", line 589, in readinto\n",
            "    return self._sock.recv_into(b)\n",
            "  File \"/usr/lib/python3.7/ssl.py\", line 1071, in recv_into\n",
            "    return self.read(nbytes, buffer)\n",
            "  File \"/usr/lib/python3.7/ssl.py\", line 929, in read\n",
            "    return self._sslobj.read(len, buffer)\n",
            "socket.timeout: The read operation timed out\n",
            "\n",
            "During handling of the above exception, another exception occurred:\n",
            "\n",
            "Traceback (most recent call last):\n",
            "  File \"/usr/local/lib/python3.7/dist-packages/geopy/extra/rate_limiter.py\", line 130, in __call__\n",
            "    return self.func(*args, **kwargs)\n",
            "  File \"/usr/local/lib/python3.7/dist-packages/geopy/geocoders/osm.py\", line 307, in geocode\n",
            "    self._call_geocoder(url, timeout=timeout), exactly_one\n",
            "  File \"/usr/local/lib/python3.7/dist-packages/geopy/geocoders/base.py\", line 371, in _call_geocoder\n",
            "    raise GeocoderTimedOut('Service timed out')\n",
            "geopy.exc.GeocoderTimedOut: Service timed out\n",
            "RateLimiter swallowed an error after 2 retries. Called with (*('PERAMIRIM, 1,SAO PAULO - SP - BRAZIL',), **{}).\n",
            "Traceback (most recent call last):\n",
            "  File \"/usr/local/lib/python3.7/dist-packages/geopy/geocoders/base.py\", line 344, in _call_geocoder\n",
            "    page = requester(req, timeout=timeout, **kwargs)\n",
            "  File \"/usr/lib/python3.7/urllib/request.py\", line 525, in open\n",
            "    response = self._open(req, data)\n",
            "  File \"/usr/lib/python3.7/urllib/request.py\", line 543, in _open\n",
            "    '_open', req)\n",
            "  File \"/usr/lib/python3.7/urllib/request.py\", line 503, in _call_chain\n",
            "    result = func(*args)\n",
            "  File \"/usr/lib/python3.7/urllib/request.py\", line 1393, in https_open\n",
            "    context=self._context, check_hostname=self._check_hostname)\n",
            "  File \"/usr/lib/python3.7/urllib/request.py\", line 1353, in do_open\n",
            "    r = h.getresponse()\n",
            "  File \"/usr/lib/python3.7/http/client.py\", line 1373, in getresponse\n",
            "    response.begin()\n",
            "  File \"/usr/lib/python3.7/http/client.py\", line 319, in begin\n",
            "    version, status, reason = self._read_status()\n",
            "  File \"/usr/lib/python3.7/http/client.py\", line 280, in _read_status\n",
            "    line = str(self.fp.readline(_MAXLINE + 1), \"iso-8859-1\")\n",
            "  File \"/usr/lib/python3.7/socket.py\", line 589, in readinto\n",
            "    return self._sock.recv_into(b)\n",
            "  File \"/usr/lib/python3.7/ssl.py\", line 1071, in recv_into\n",
            "    return self.read(nbytes, buffer)\n",
            "  File \"/usr/lib/python3.7/ssl.py\", line 929, in read\n",
            "    return self._sslobj.read(len, buffer)\n",
            "socket.timeout: The read operation timed out\n",
            "\n",
            "During handling of the above exception, another exception occurred:\n",
            "\n",
            "Traceback (most recent call last):\n",
            "  File \"/usr/local/lib/python3.7/dist-packages/geopy/extra/rate_limiter.py\", line 130, in __call__\n",
            "    return self.func(*args, **kwargs)\n",
            "  File \"/usr/local/lib/python3.7/dist-packages/geopy/geocoders/osm.py\", line 307, in geocode\n",
            "    self._call_geocoder(url, timeout=timeout), exactly_one\n",
            "  File \"/usr/local/lib/python3.7/dist-packages/geopy/geocoders/base.py\", line 371, in _call_geocoder\n",
            "    raise GeocoderTimedOut('Service timed out')\n",
            "geopy.exc.GeocoderTimedOut: Service timed out\n",
            "RateLimiter caught an error, retrying (0/2 tries). Called with (*('RUA NOSSA SENHORA APARECIDA, 342,SAO PAULO - SP - BRAZIL',), **{}).\n",
            "Traceback (most recent call last):\n",
            "  File \"/usr/local/lib/python3.7/dist-packages/geopy/geocoders/base.py\", line 344, in _call_geocoder\n",
            "    page = requester(req, timeout=timeout, **kwargs)\n",
            "  File \"/usr/lib/python3.7/urllib/request.py\", line 525, in open\n",
            "    response = self._open(req, data)\n",
            "  File \"/usr/lib/python3.7/urllib/request.py\", line 543, in _open\n",
            "    '_open', req)\n",
            "  File \"/usr/lib/python3.7/urllib/request.py\", line 503, in _call_chain\n",
            "    result = func(*args)\n",
            "  File \"/usr/lib/python3.7/urllib/request.py\", line 1393, in https_open\n",
            "    context=self._context, check_hostname=self._check_hostname)\n",
            "  File \"/usr/lib/python3.7/urllib/request.py\", line 1353, in do_open\n",
            "    r = h.getresponse()\n",
            "  File \"/usr/lib/python3.7/http/client.py\", line 1373, in getresponse\n",
            "    response.begin()\n",
            "  File \"/usr/lib/python3.7/http/client.py\", line 319, in begin\n",
            "    version, status, reason = self._read_status()\n",
            "  File \"/usr/lib/python3.7/http/client.py\", line 280, in _read_status\n",
            "    line = str(self.fp.readline(_MAXLINE + 1), \"iso-8859-1\")\n",
            "  File \"/usr/lib/python3.7/socket.py\", line 589, in readinto\n",
            "    return self._sock.recv_into(b)\n",
            "  File \"/usr/lib/python3.7/ssl.py\", line 1071, in recv_into\n",
            "    return self.read(nbytes, buffer)\n",
            "  File \"/usr/lib/python3.7/ssl.py\", line 929, in read\n",
            "    return self._sslobj.read(len, buffer)\n",
            "socket.timeout: The read operation timed out\n",
            "\n",
            "During handling of the above exception, another exception occurred:\n",
            "\n",
            "Traceback (most recent call last):\n",
            "  File \"/usr/local/lib/python3.7/dist-packages/geopy/extra/rate_limiter.py\", line 130, in __call__\n",
            "    return self.func(*args, **kwargs)\n",
            "  File \"/usr/local/lib/python3.7/dist-packages/geopy/geocoders/osm.py\", line 307, in geocode\n",
            "    self._call_geocoder(url, timeout=timeout), exactly_one\n",
            "  File \"/usr/local/lib/python3.7/dist-packages/geopy/geocoders/base.py\", line 371, in _call_geocoder\n",
            "    raise GeocoderTimedOut('Service timed out')\n",
            "geopy.exc.GeocoderTimedOut: Service timed out\n",
            "RateLimiter caught an error, retrying (1/2 tries). Called with (*('RUA NOSSA SENHORA APARECIDA, 342,SAO PAULO - SP - BRAZIL',), **{}).\n",
            "Traceback (most recent call last):\n",
            "  File \"/usr/local/lib/python3.7/dist-packages/geopy/geocoders/base.py\", line 344, in _call_geocoder\n",
            "    page = requester(req, timeout=timeout, **kwargs)\n",
            "  File \"/usr/lib/python3.7/urllib/request.py\", line 525, in open\n",
            "    response = self._open(req, data)\n",
            "  File \"/usr/lib/python3.7/urllib/request.py\", line 543, in _open\n",
            "    '_open', req)\n",
            "  File \"/usr/lib/python3.7/urllib/request.py\", line 503, in _call_chain\n",
            "    result = func(*args)\n",
            "  File \"/usr/lib/python3.7/urllib/request.py\", line 1393, in https_open\n",
            "    context=self._context, check_hostname=self._check_hostname)\n",
            "  File \"/usr/lib/python3.7/urllib/request.py\", line 1353, in do_open\n",
            "    r = h.getresponse()\n",
            "  File \"/usr/lib/python3.7/http/client.py\", line 1373, in getresponse\n",
            "    response.begin()\n",
            "  File \"/usr/lib/python3.7/http/client.py\", line 319, in begin\n",
            "    version, status, reason = self._read_status()\n",
            "  File \"/usr/lib/python3.7/http/client.py\", line 280, in _read_status\n",
            "    line = str(self.fp.readline(_MAXLINE + 1), \"iso-8859-1\")\n",
            "  File \"/usr/lib/python3.7/socket.py\", line 589, in readinto\n",
            "    return self._sock.recv_into(b)\n",
            "  File \"/usr/lib/python3.7/ssl.py\", line 1071, in recv_into\n",
            "    return self.read(nbytes, buffer)\n",
            "  File \"/usr/lib/python3.7/ssl.py\", line 929, in read\n",
            "    return self._sslobj.read(len, buffer)\n",
            "socket.timeout: The read operation timed out\n",
            "\n",
            "During handling of the above exception, another exception occurred:\n",
            "\n",
            "Traceback (most recent call last):\n",
            "  File \"/usr/local/lib/python3.7/dist-packages/geopy/extra/rate_limiter.py\", line 130, in __call__\n",
            "    return self.func(*args, **kwargs)\n",
            "  File \"/usr/local/lib/python3.7/dist-packages/geopy/geocoders/osm.py\", line 307, in geocode\n",
            "    self._call_geocoder(url, timeout=timeout), exactly_one\n",
            "  File \"/usr/local/lib/python3.7/dist-packages/geopy/geocoders/base.py\", line 371, in _call_geocoder\n",
            "    raise GeocoderTimedOut('Service timed out')\n",
            "geopy.exc.GeocoderTimedOut: Service timed out\n",
            "RateLimiter swallowed an error after 2 retries. Called with (*('RUA NOSSA SENHORA APARECIDA, 342,SAO PAULO - SP - BRAZIL',), **{}).\n",
            "Traceback (most recent call last):\n",
            "  File \"/usr/local/lib/python3.7/dist-packages/geopy/geocoders/base.py\", line 344, in _call_geocoder\n",
            "    page = requester(req, timeout=timeout, **kwargs)\n",
            "  File \"/usr/lib/python3.7/urllib/request.py\", line 525, in open\n",
            "    response = self._open(req, data)\n",
            "  File \"/usr/lib/python3.7/urllib/request.py\", line 543, in _open\n",
            "    '_open', req)\n",
            "  File \"/usr/lib/python3.7/urllib/request.py\", line 503, in _call_chain\n",
            "    result = func(*args)\n",
            "  File \"/usr/lib/python3.7/urllib/request.py\", line 1393, in https_open\n",
            "    context=self._context, check_hostname=self._check_hostname)\n",
            "  File \"/usr/lib/python3.7/urllib/request.py\", line 1353, in do_open\n",
            "    r = h.getresponse()\n",
            "  File \"/usr/lib/python3.7/http/client.py\", line 1373, in getresponse\n",
            "    response.begin()\n",
            "  File \"/usr/lib/python3.7/http/client.py\", line 319, in begin\n",
            "    version, status, reason = self._read_status()\n",
            "  File \"/usr/lib/python3.7/http/client.py\", line 280, in _read_status\n",
            "    line = str(self.fp.readline(_MAXLINE + 1), \"iso-8859-1\")\n",
            "  File \"/usr/lib/python3.7/socket.py\", line 589, in readinto\n",
            "    return self._sock.recv_into(b)\n",
            "  File \"/usr/lib/python3.7/ssl.py\", line 1071, in recv_into\n",
            "    return self.read(nbytes, buffer)\n",
            "  File \"/usr/lib/python3.7/ssl.py\", line 929, in read\n",
            "    return self._sslobj.read(len, buffer)\n",
            "socket.timeout: The read operation timed out\n",
            "\n",
            "During handling of the above exception, another exception occurred:\n",
            "\n",
            "Traceback (most recent call last):\n",
            "  File \"/usr/local/lib/python3.7/dist-packages/geopy/extra/rate_limiter.py\", line 130, in __call__\n",
            "    return self.func(*args, **kwargs)\n",
            "  File \"/usr/local/lib/python3.7/dist-packages/geopy/geocoders/osm.py\", line 307, in geocode\n",
            "    self._call_geocoder(url, timeout=timeout), exactly_one\n",
            "  File \"/usr/local/lib/python3.7/dist-packages/geopy/geocoders/base.py\", line 371, in _call_geocoder\n",
            "    raise GeocoderTimedOut('Service timed out')\n",
            "geopy.exc.GeocoderTimedOut: Service timed out\n",
            "RateLimiter caught an error, retrying (0/2 tries). Called with (*('GUARUVA, 429,SAO PAULO - SP - BRAZIL',), **{}).\n",
            "Traceback (most recent call last):\n",
            "  File \"/usr/local/lib/python3.7/dist-packages/geopy/geocoders/base.py\", line 344, in _call_geocoder\n",
            "    page = requester(req, timeout=timeout, **kwargs)\n",
            "  File \"/usr/lib/python3.7/urllib/request.py\", line 525, in open\n",
            "    response = self._open(req, data)\n",
            "  File \"/usr/lib/python3.7/urllib/request.py\", line 543, in _open\n",
            "    '_open', req)\n",
            "  File \"/usr/lib/python3.7/urllib/request.py\", line 503, in _call_chain\n",
            "    result = func(*args)\n",
            "  File \"/usr/lib/python3.7/urllib/request.py\", line 1393, in https_open\n",
            "    context=self._context, check_hostname=self._check_hostname)\n",
            "  File \"/usr/lib/python3.7/urllib/request.py\", line 1353, in do_open\n",
            "    r = h.getresponse()\n",
            "  File \"/usr/lib/python3.7/http/client.py\", line 1373, in getresponse\n",
            "    response.begin()\n",
            "  File \"/usr/lib/python3.7/http/client.py\", line 319, in begin\n",
            "    version, status, reason = self._read_status()\n",
            "  File \"/usr/lib/python3.7/http/client.py\", line 280, in _read_status\n",
            "    line = str(self.fp.readline(_MAXLINE + 1), \"iso-8859-1\")\n",
            "  File \"/usr/lib/python3.7/socket.py\", line 589, in readinto\n",
            "    return self._sock.recv_into(b)\n",
            "  File \"/usr/lib/python3.7/ssl.py\", line 1071, in recv_into\n",
            "    return self.read(nbytes, buffer)\n",
            "  File \"/usr/lib/python3.7/ssl.py\", line 929, in read\n",
            "    return self._sslobj.read(len, buffer)\n",
            "socket.timeout: The read operation timed out\n",
            "\n",
            "During handling of the above exception, another exception occurred:\n",
            "\n",
            "Traceback (most recent call last):\n",
            "  File \"/usr/local/lib/python3.7/dist-packages/geopy/extra/rate_limiter.py\", line 130, in __call__\n",
            "    return self.func(*args, **kwargs)\n",
            "  File \"/usr/local/lib/python3.7/dist-packages/geopy/geocoders/osm.py\", line 307, in geocode\n",
            "    self._call_geocoder(url, timeout=timeout), exactly_one\n",
            "  File \"/usr/local/lib/python3.7/dist-packages/geopy/geocoders/base.py\", line 371, in _call_geocoder\n",
            "    raise GeocoderTimedOut('Service timed out')\n",
            "geopy.exc.GeocoderTimedOut: Service timed out\n",
            "RateLimiter caught an error, retrying (1/2 tries). Called with (*('GUARUVA, 429,SAO PAULO - SP - BRAZIL',), **{}).\n",
            "Traceback (most recent call last):\n",
            "  File \"/usr/local/lib/python3.7/dist-packages/geopy/geocoders/base.py\", line 344, in _call_geocoder\n",
            "    page = requester(req, timeout=timeout, **kwargs)\n",
            "  File \"/usr/lib/python3.7/urllib/request.py\", line 525, in open\n",
            "    response = self._open(req, data)\n",
            "  File \"/usr/lib/python3.7/urllib/request.py\", line 543, in _open\n",
            "    '_open', req)\n",
            "  File \"/usr/lib/python3.7/urllib/request.py\", line 503, in _call_chain\n",
            "    result = func(*args)\n",
            "  File \"/usr/lib/python3.7/urllib/request.py\", line 1393, in https_open\n",
            "    context=self._context, check_hostname=self._check_hostname)\n",
            "  File \"/usr/lib/python3.7/urllib/request.py\", line 1353, in do_open\n",
            "    r = h.getresponse()\n",
            "  File \"/usr/lib/python3.7/http/client.py\", line 1373, in getresponse\n",
            "    response.begin()\n",
            "  File \"/usr/lib/python3.7/http/client.py\", line 319, in begin\n",
            "    version, status, reason = self._read_status()\n",
            "  File \"/usr/lib/python3.7/http/client.py\", line 280, in _read_status\n",
            "    line = str(self.fp.readline(_MAXLINE + 1), \"iso-8859-1\")\n",
            "  File \"/usr/lib/python3.7/socket.py\", line 589, in readinto\n",
            "    return self._sock.recv_into(b)\n",
            "  File \"/usr/lib/python3.7/ssl.py\", line 1071, in recv_into\n",
            "    return self.read(nbytes, buffer)\n",
            "  File \"/usr/lib/python3.7/ssl.py\", line 929, in read\n",
            "    return self._sslobj.read(len, buffer)\n",
            "socket.timeout: The read operation timed out\n",
            "\n",
            "During handling of the above exception, another exception occurred:\n",
            "\n",
            "Traceback (most recent call last):\n",
            "  File \"/usr/local/lib/python3.7/dist-packages/geopy/extra/rate_limiter.py\", line 130, in __call__\n",
            "    return self.func(*args, **kwargs)\n",
            "  File \"/usr/local/lib/python3.7/dist-packages/geopy/geocoders/osm.py\", line 307, in geocode\n",
            "    self._call_geocoder(url, timeout=timeout), exactly_one\n",
            "  File \"/usr/local/lib/python3.7/dist-packages/geopy/geocoders/base.py\", line 371, in _call_geocoder\n",
            "    raise GeocoderTimedOut('Service timed out')\n",
            "geopy.exc.GeocoderTimedOut: Service timed out\n",
            "RateLimiter swallowed an error after 2 retries. Called with (*('GUARUVA, 429,SAO PAULO - SP - BRAZIL',), **{}).\n",
            "Traceback (most recent call last):\n",
            "  File \"/usr/local/lib/python3.7/dist-packages/geopy/geocoders/base.py\", line 344, in _call_geocoder\n",
            "    page = requester(req, timeout=timeout, **kwargs)\n",
            "  File \"/usr/lib/python3.7/urllib/request.py\", line 525, in open\n",
            "    response = self._open(req, data)\n",
            "  File \"/usr/lib/python3.7/urllib/request.py\", line 543, in _open\n",
            "    '_open', req)\n",
            "  File \"/usr/lib/python3.7/urllib/request.py\", line 503, in _call_chain\n",
            "    result = func(*args)\n",
            "  File \"/usr/lib/python3.7/urllib/request.py\", line 1393, in https_open\n",
            "    context=self._context, check_hostname=self._check_hostname)\n",
            "  File \"/usr/lib/python3.7/urllib/request.py\", line 1353, in do_open\n",
            "    r = h.getresponse()\n",
            "  File \"/usr/lib/python3.7/http/client.py\", line 1373, in getresponse\n",
            "    response.begin()\n",
            "  File \"/usr/lib/python3.7/http/client.py\", line 319, in begin\n",
            "    version, status, reason = self._read_status()\n",
            "  File \"/usr/lib/python3.7/http/client.py\", line 280, in _read_status\n",
            "    line = str(self.fp.readline(_MAXLINE + 1), \"iso-8859-1\")\n",
            "  File \"/usr/lib/python3.7/socket.py\", line 589, in readinto\n",
            "    return self._sock.recv_into(b)\n",
            "  File \"/usr/lib/python3.7/ssl.py\", line 1071, in recv_into\n",
            "    return self.read(nbytes, buffer)\n",
            "  File \"/usr/lib/python3.7/ssl.py\", line 929, in read\n",
            "    return self._sslobj.read(len, buffer)\n",
            "socket.timeout: The read operation timed out\n",
            "\n",
            "During handling of the above exception, another exception occurred:\n",
            "\n",
            "Traceback (most recent call last):\n",
            "  File \"/usr/local/lib/python3.7/dist-packages/geopy/extra/rate_limiter.py\", line 130, in __call__\n",
            "    return self.func(*args, **kwargs)\n",
            "  File \"/usr/local/lib/python3.7/dist-packages/geopy/geocoders/osm.py\", line 307, in geocode\n",
            "    self._call_geocoder(url, timeout=timeout), exactly_one\n",
            "  File \"/usr/local/lib/python3.7/dist-packages/geopy/geocoders/base.py\", line 371, in _call_geocoder\n",
            "    raise GeocoderTimedOut('Service timed out')\n",
            "geopy.exc.GeocoderTimedOut: Service timed out\n",
            "RateLimiter caught an error, retrying (0/2 tries). Called with (*('AV SAO PAULO, 23,SAO PAULO - SP - BRAZIL',), **{}).\n",
            "Traceback (most recent call last):\n",
            "  File \"/usr/local/lib/python3.7/dist-packages/geopy/geocoders/base.py\", line 344, in _call_geocoder\n",
            "    page = requester(req, timeout=timeout, **kwargs)\n",
            "  File \"/usr/lib/python3.7/urllib/request.py\", line 525, in open\n",
            "    response = self._open(req, data)\n",
            "  File \"/usr/lib/python3.7/urllib/request.py\", line 543, in _open\n",
            "    '_open', req)\n",
            "  File \"/usr/lib/python3.7/urllib/request.py\", line 503, in _call_chain\n",
            "    result = func(*args)\n",
            "  File \"/usr/lib/python3.7/urllib/request.py\", line 1393, in https_open\n",
            "    context=self._context, check_hostname=self._check_hostname)\n",
            "  File \"/usr/lib/python3.7/urllib/request.py\", line 1353, in do_open\n",
            "    r = h.getresponse()\n",
            "  File \"/usr/lib/python3.7/http/client.py\", line 1373, in getresponse\n",
            "    response.begin()\n",
            "  File \"/usr/lib/python3.7/http/client.py\", line 319, in begin\n",
            "    version, status, reason = self._read_status()\n",
            "  File \"/usr/lib/python3.7/http/client.py\", line 280, in _read_status\n",
            "    line = str(self.fp.readline(_MAXLINE + 1), \"iso-8859-1\")\n",
            "  File \"/usr/lib/python3.7/socket.py\", line 589, in readinto\n",
            "    return self._sock.recv_into(b)\n",
            "  File \"/usr/lib/python3.7/ssl.py\", line 1071, in recv_into\n",
            "    return self.read(nbytes, buffer)\n",
            "  File \"/usr/lib/python3.7/ssl.py\", line 929, in read\n",
            "    return self._sslobj.read(len, buffer)\n",
            "socket.timeout: The read operation timed out\n",
            "\n",
            "During handling of the above exception, another exception occurred:\n",
            "\n",
            "Traceback (most recent call last):\n",
            "  File \"/usr/local/lib/python3.7/dist-packages/geopy/extra/rate_limiter.py\", line 130, in __call__\n",
            "    return self.func(*args, **kwargs)\n",
            "  File \"/usr/local/lib/python3.7/dist-packages/geopy/geocoders/osm.py\", line 307, in geocode\n",
            "    self._call_geocoder(url, timeout=timeout), exactly_one\n",
            "  File \"/usr/local/lib/python3.7/dist-packages/geopy/geocoders/base.py\", line 371, in _call_geocoder\n",
            "    raise GeocoderTimedOut('Service timed out')\n",
            "geopy.exc.GeocoderTimedOut: Service timed out\n",
            "RateLimiter caught an error, retrying (1/2 tries). Called with (*('AV SAO PAULO, 23,SAO PAULO - SP - BRAZIL',), **{}).\n",
            "Traceback (most recent call last):\n",
            "  File \"/usr/local/lib/python3.7/dist-packages/geopy/geocoders/base.py\", line 344, in _call_geocoder\n",
            "    page = requester(req, timeout=timeout, **kwargs)\n",
            "  File \"/usr/lib/python3.7/urllib/request.py\", line 525, in open\n",
            "    response = self._open(req, data)\n",
            "  File \"/usr/lib/python3.7/urllib/request.py\", line 543, in _open\n",
            "    '_open', req)\n",
            "  File \"/usr/lib/python3.7/urllib/request.py\", line 503, in _call_chain\n",
            "    result = func(*args)\n",
            "  File \"/usr/lib/python3.7/urllib/request.py\", line 1393, in https_open\n",
            "    context=self._context, check_hostname=self._check_hostname)\n",
            "  File \"/usr/lib/python3.7/urllib/request.py\", line 1353, in do_open\n",
            "    r = h.getresponse()\n",
            "  File \"/usr/lib/python3.7/http/client.py\", line 1373, in getresponse\n",
            "    response.begin()\n",
            "  File \"/usr/lib/python3.7/http/client.py\", line 319, in begin\n",
            "    version, status, reason = self._read_status()\n",
            "  File \"/usr/lib/python3.7/http/client.py\", line 280, in _read_status\n",
            "    line = str(self.fp.readline(_MAXLINE + 1), \"iso-8859-1\")\n",
            "  File \"/usr/lib/python3.7/socket.py\", line 589, in readinto\n",
            "    return self._sock.recv_into(b)\n",
            "  File \"/usr/lib/python3.7/ssl.py\", line 1071, in recv_into\n",
            "    return self.read(nbytes, buffer)\n",
            "  File \"/usr/lib/python3.7/ssl.py\", line 929, in read\n",
            "    return self._sslobj.read(len, buffer)\n",
            "socket.timeout: The read operation timed out\n",
            "\n",
            "During handling of the above exception, another exception occurred:\n",
            "\n",
            "Traceback (most recent call last):\n",
            "  File \"/usr/local/lib/python3.7/dist-packages/geopy/extra/rate_limiter.py\", line 130, in __call__\n",
            "    return self.func(*args, **kwargs)\n",
            "  File \"/usr/local/lib/python3.7/dist-packages/geopy/geocoders/osm.py\", line 307, in geocode\n",
            "    self._call_geocoder(url, timeout=timeout), exactly_one\n",
            "  File \"/usr/local/lib/python3.7/dist-packages/geopy/geocoders/base.py\", line 371, in _call_geocoder\n",
            "    raise GeocoderTimedOut('Service timed out')\n",
            "geopy.exc.GeocoderTimedOut: Service timed out\n",
            "RateLimiter swallowed an error after 2 retries. Called with (*('AV SAO PAULO, 23,SAO PAULO - SP - BRAZIL',), **{}).\n",
            "Traceback (most recent call last):\n",
            "  File \"/usr/local/lib/python3.7/dist-packages/geopy/geocoders/base.py\", line 344, in _call_geocoder\n",
            "    page = requester(req, timeout=timeout, **kwargs)\n",
            "  File \"/usr/lib/python3.7/urllib/request.py\", line 525, in open\n",
            "    response = self._open(req, data)\n",
            "  File \"/usr/lib/python3.7/urllib/request.py\", line 543, in _open\n",
            "    '_open', req)\n",
            "  File \"/usr/lib/python3.7/urllib/request.py\", line 503, in _call_chain\n",
            "    result = func(*args)\n",
            "  File \"/usr/lib/python3.7/urllib/request.py\", line 1393, in https_open\n",
            "    context=self._context, check_hostname=self._check_hostname)\n",
            "  File \"/usr/lib/python3.7/urllib/request.py\", line 1353, in do_open\n",
            "    r = h.getresponse()\n",
            "  File \"/usr/lib/python3.7/http/client.py\", line 1373, in getresponse\n",
            "    response.begin()\n",
            "  File \"/usr/lib/python3.7/http/client.py\", line 319, in begin\n",
            "    version, status, reason = self._read_status()\n",
            "  File \"/usr/lib/python3.7/http/client.py\", line 280, in _read_status\n",
            "    line = str(self.fp.readline(_MAXLINE + 1), \"iso-8859-1\")\n",
            "  File \"/usr/lib/python3.7/socket.py\", line 589, in readinto\n",
            "    return self._sock.recv_into(b)\n",
            "  File \"/usr/lib/python3.7/ssl.py\", line 1071, in recv_into\n",
            "    return self.read(nbytes, buffer)\n",
            "  File \"/usr/lib/python3.7/ssl.py\", line 929, in read\n",
            "    return self._sslobj.read(len, buffer)\n",
            "socket.timeout: The read operation timed out\n",
            "\n",
            "During handling of the above exception, another exception occurred:\n",
            "\n",
            "Traceback (most recent call last):\n",
            "  File \"/usr/local/lib/python3.7/dist-packages/geopy/extra/rate_limiter.py\", line 130, in __call__\n",
            "    return self.func(*args, **kwargs)\n",
            "  File \"/usr/local/lib/python3.7/dist-packages/geopy/geocoders/osm.py\", line 307, in geocode\n",
            "    self._call_geocoder(url, timeout=timeout), exactly_one\n",
            "  File \"/usr/local/lib/python3.7/dist-packages/geopy/geocoders/base.py\", line 371, in _call_geocoder\n",
            "    raise GeocoderTimedOut('Service timed out')\n",
            "geopy.exc.GeocoderTimedOut: Service timed out\n",
            "RateLimiter caught an error, retrying (0/2 tries). Called with (*('RUA DOIS, 3,SAO PAULO - SP - BRAZIL',), **{}).\n",
            "Traceback (most recent call last):\n",
            "  File \"/usr/local/lib/python3.7/dist-packages/geopy/geocoders/base.py\", line 344, in _call_geocoder\n",
            "    page = requester(req, timeout=timeout, **kwargs)\n",
            "  File \"/usr/lib/python3.7/urllib/request.py\", line 525, in open\n",
            "    response = self._open(req, data)\n",
            "  File \"/usr/lib/python3.7/urllib/request.py\", line 543, in _open\n",
            "    '_open', req)\n",
            "  File \"/usr/lib/python3.7/urllib/request.py\", line 503, in _call_chain\n",
            "    result = func(*args)\n",
            "  File \"/usr/lib/python3.7/urllib/request.py\", line 1393, in https_open\n",
            "    context=self._context, check_hostname=self._check_hostname)\n",
            "  File \"/usr/lib/python3.7/urllib/request.py\", line 1353, in do_open\n",
            "    r = h.getresponse()\n",
            "  File \"/usr/lib/python3.7/http/client.py\", line 1373, in getresponse\n",
            "    response.begin()\n",
            "  File \"/usr/lib/python3.7/http/client.py\", line 319, in begin\n",
            "    version, status, reason = self._read_status()\n",
            "  File \"/usr/lib/python3.7/http/client.py\", line 280, in _read_status\n",
            "    line = str(self.fp.readline(_MAXLINE + 1), \"iso-8859-1\")\n",
            "  File \"/usr/lib/python3.7/socket.py\", line 589, in readinto\n",
            "    return self._sock.recv_into(b)\n",
            "  File \"/usr/lib/python3.7/ssl.py\", line 1071, in recv_into\n",
            "    return self.read(nbytes, buffer)\n",
            "  File \"/usr/lib/python3.7/ssl.py\", line 929, in read\n",
            "    return self._sslobj.read(len, buffer)\n",
            "socket.timeout: The read operation timed out\n",
            "\n",
            "During handling of the above exception, another exception occurred:\n",
            "\n",
            "Traceback (most recent call last):\n",
            "  File \"/usr/local/lib/python3.7/dist-packages/geopy/extra/rate_limiter.py\", line 130, in __call__\n",
            "    return self.func(*args, **kwargs)\n",
            "  File \"/usr/local/lib/python3.7/dist-packages/geopy/geocoders/osm.py\", line 307, in geocode\n",
            "    self._call_geocoder(url, timeout=timeout), exactly_one\n",
            "  File \"/usr/local/lib/python3.7/dist-packages/geopy/geocoders/base.py\", line 371, in _call_geocoder\n",
            "    raise GeocoderTimedOut('Service timed out')\n",
            "geopy.exc.GeocoderTimedOut: Service timed out\n",
            "RateLimiter caught an error, retrying (1/2 tries). Called with (*('RUA DOIS, 3,SAO PAULO - SP - BRAZIL',), **{}).\n",
            "Traceback (most recent call last):\n",
            "  File \"/usr/local/lib/python3.7/dist-packages/geopy/geocoders/base.py\", line 344, in _call_geocoder\n",
            "    page = requester(req, timeout=timeout, **kwargs)\n",
            "  File \"/usr/lib/python3.7/urllib/request.py\", line 525, in open\n",
            "    response = self._open(req, data)\n",
            "  File \"/usr/lib/python3.7/urllib/request.py\", line 543, in _open\n",
            "    '_open', req)\n",
            "  File \"/usr/lib/python3.7/urllib/request.py\", line 503, in _call_chain\n",
            "    result = func(*args)\n",
            "  File \"/usr/lib/python3.7/urllib/request.py\", line 1393, in https_open\n",
            "    context=self._context, check_hostname=self._check_hostname)\n",
            "  File \"/usr/lib/python3.7/urllib/request.py\", line 1353, in do_open\n",
            "    r = h.getresponse()\n",
            "  File \"/usr/lib/python3.7/http/client.py\", line 1373, in getresponse\n",
            "    response.begin()\n",
            "  File \"/usr/lib/python3.7/http/client.py\", line 319, in begin\n",
            "    version, status, reason = self._read_status()\n",
            "  File \"/usr/lib/python3.7/http/client.py\", line 280, in _read_status\n",
            "    line = str(self.fp.readline(_MAXLINE + 1), \"iso-8859-1\")\n",
            "  File \"/usr/lib/python3.7/socket.py\", line 589, in readinto\n",
            "    return self._sock.recv_into(b)\n",
            "  File \"/usr/lib/python3.7/ssl.py\", line 1071, in recv_into\n",
            "    return self.read(nbytes, buffer)\n",
            "  File \"/usr/lib/python3.7/ssl.py\", line 929, in read\n",
            "    return self._sslobj.read(len, buffer)\n",
            "socket.timeout: The read operation timed out\n",
            "\n",
            "During handling of the above exception, another exception occurred:\n",
            "\n",
            "Traceback (most recent call last):\n",
            "  File \"/usr/local/lib/python3.7/dist-packages/geopy/extra/rate_limiter.py\", line 130, in __call__\n",
            "    return self.func(*args, **kwargs)\n",
            "  File \"/usr/local/lib/python3.7/dist-packages/geopy/geocoders/osm.py\", line 307, in geocode\n",
            "    self._call_geocoder(url, timeout=timeout), exactly_one\n",
            "  File \"/usr/local/lib/python3.7/dist-packages/geopy/geocoders/base.py\", line 371, in _call_geocoder\n",
            "    raise GeocoderTimedOut('Service timed out')\n",
            "geopy.exc.GeocoderTimedOut: Service timed out\n",
            "RateLimiter swallowed an error after 2 retries. Called with (*('RUA DOIS, 3,SAO PAULO - SP - BRAZIL',), **{}).\n",
            "Traceback (most recent call last):\n",
            "  File \"/usr/local/lib/python3.7/dist-packages/geopy/geocoders/base.py\", line 344, in _call_geocoder\n",
            "    page = requester(req, timeout=timeout, **kwargs)\n",
            "  File \"/usr/lib/python3.7/urllib/request.py\", line 525, in open\n",
            "    response = self._open(req, data)\n",
            "  File \"/usr/lib/python3.7/urllib/request.py\", line 543, in _open\n",
            "    '_open', req)\n",
            "  File \"/usr/lib/python3.7/urllib/request.py\", line 503, in _call_chain\n",
            "    result = func(*args)\n",
            "  File \"/usr/lib/python3.7/urllib/request.py\", line 1393, in https_open\n",
            "    context=self._context, check_hostname=self._check_hostname)\n",
            "  File \"/usr/lib/python3.7/urllib/request.py\", line 1353, in do_open\n",
            "    r = h.getresponse()\n",
            "  File \"/usr/lib/python3.7/http/client.py\", line 1373, in getresponse\n",
            "    response.begin()\n",
            "  File \"/usr/lib/python3.7/http/client.py\", line 319, in begin\n",
            "    version, status, reason = self._read_status()\n",
            "  File \"/usr/lib/python3.7/http/client.py\", line 280, in _read_status\n",
            "    line = str(self.fp.readline(_MAXLINE + 1), \"iso-8859-1\")\n",
            "  File \"/usr/lib/python3.7/socket.py\", line 589, in readinto\n",
            "    return self._sock.recv_into(b)\n",
            "  File \"/usr/lib/python3.7/ssl.py\", line 1071, in recv_into\n",
            "    return self.read(nbytes, buffer)\n",
            "  File \"/usr/lib/python3.7/ssl.py\", line 929, in read\n",
            "    return self._sslobj.read(len, buffer)\n",
            "socket.timeout: The read operation timed out\n",
            "\n",
            "During handling of the above exception, another exception occurred:\n",
            "\n",
            "Traceback (most recent call last):\n",
            "  File \"/usr/local/lib/python3.7/dist-packages/geopy/extra/rate_limiter.py\", line 130, in __call__\n",
            "    return self.func(*args, **kwargs)\n",
            "  File \"/usr/local/lib/python3.7/dist-packages/geopy/geocoders/osm.py\", line 307, in geocode\n",
            "    self._call_geocoder(url, timeout=timeout), exactly_one\n",
            "  File \"/usr/local/lib/python3.7/dist-packages/geopy/geocoders/base.py\", line 371, in _call_geocoder\n",
            "    raise GeocoderTimedOut('Service timed out')\n",
            "geopy.exc.GeocoderTimedOut: Service timed out\n",
            "RateLimiter caught an error, retrying (0/2 tries). Called with (*('MUANA, 214,SAO PAULO - SP - BRAZIL',), **{}).\n",
            "Traceback (most recent call last):\n",
            "  File \"/usr/local/lib/python3.7/dist-packages/geopy/geocoders/base.py\", line 344, in _call_geocoder\n",
            "    page = requester(req, timeout=timeout, **kwargs)\n",
            "  File \"/usr/lib/python3.7/urllib/request.py\", line 525, in open\n",
            "    response = self._open(req, data)\n",
            "  File \"/usr/lib/python3.7/urllib/request.py\", line 543, in _open\n",
            "    '_open', req)\n",
            "  File \"/usr/lib/python3.7/urllib/request.py\", line 503, in _call_chain\n",
            "    result = func(*args)\n",
            "  File \"/usr/lib/python3.7/urllib/request.py\", line 1393, in https_open\n",
            "    context=self._context, check_hostname=self._check_hostname)\n",
            "  File \"/usr/lib/python3.7/urllib/request.py\", line 1353, in do_open\n",
            "    r = h.getresponse()\n",
            "  File \"/usr/lib/python3.7/http/client.py\", line 1373, in getresponse\n",
            "    response.begin()\n",
            "  File \"/usr/lib/python3.7/http/client.py\", line 319, in begin\n",
            "    version, status, reason = self._read_status()\n",
            "  File \"/usr/lib/python3.7/http/client.py\", line 280, in _read_status\n",
            "    line = str(self.fp.readline(_MAXLINE + 1), \"iso-8859-1\")\n",
            "  File \"/usr/lib/python3.7/socket.py\", line 589, in readinto\n",
            "    return self._sock.recv_into(b)\n",
            "  File \"/usr/lib/python3.7/ssl.py\", line 1071, in recv_into\n",
            "    return self.read(nbytes, buffer)\n",
            "  File \"/usr/lib/python3.7/ssl.py\", line 929, in read\n",
            "    return self._sslobj.read(len, buffer)\n",
            "socket.timeout: The read operation timed out\n",
            "\n",
            "During handling of the above exception, another exception occurred:\n",
            "\n",
            "Traceback (most recent call last):\n",
            "  File \"/usr/local/lib/python3.7/dist-packages/geopy/extra/rate_limiter.py\", line 130, in __call__\n",
            "    return self.func(*args, **kwargs)\n",
            "  File \"/usr/local/lib/python3.7/dist-packages/geopy/geocoders/osm.py\", line 307, in geocode\n",
            "    self._call_geocoder(url, timeout=timeout), exactly_one\n",
            "  File \"/usr/local/lib/python3.7/dist-packages/geopy/geocoders/base.py\", line 371, in _call_geocoder\n",
            "    raise GeocoderTimedOut('Service timed out')\n",
            "geopy.exc.GeocoderTimedOut: Service timed out\n",
            "RateLimiter caught an error, retrying (1/2 tries). Called with (*('MUANA, 214,SAO PAULO - SP - BRAZIL',), **{}).\n",
            "Traceback (most recent call last):\n",
            "  File \"/usr/local/lib/python3.7/dist-packages/geopy/geocoders/base.py\", line 344, in _call_geocoder\n",
            "    page = requester(req, timeout=timeout, **kwargs)\n",
            "  File \"/usr/lib/python3.7/urllib/request.py\", line 525, in open\n",
            "    response = self._open(req, data)\n",
            "  File \"/usr/lib/python3.7/urllib/request.py\", line 543, in _open\n",
            "    '_open', req)\n",
            "  File \"/usr/lib/python3.7/urllib/request.py\", line 503, in _call_chain\n",
            "    result = func(*args)\n",
            "  File \"/usr/lib/python3.7/urllib/request.py\", line 1393, in https_open\n",
            "    context=self._context, check_hostname=self._check_hostname)\n",
            "  File \"/usr/lib/python3.7/urllib/request.py\", line 1353, in do_open\n",
            "    r = h.getresponse()\n",
            "  File \"/usr/lib/python3.7/http/client.py\", line 1373, in getresponse\n",
            "    response.begin()\n",
            "  File \"/usr/lib/python3.7/http/client.py\", line 319, in begin\n",
            "    version, status, reason = self._read_status()\n",
            "  File \"/usr/lib/python3.7/http/client.py\", line 280, in _read_status\n",
            "    line = str(self.fp.readline(_MAXLINE + 1), \"iso-8859-1\")\n",
            "  File \"/usr/lib/python3.7/socket.py\", line 589, in readinto\n",
            "    return self._sock.recv_into(b)\n",
            "  File \"/usr/lib/python3.7/ssl.py\", line 1071, in recv_into\n",
            "    return self.read(nbytes, buffer)\n",
            "  File \"/usr/lib/python3.7/ssl.py\", line 929, in read\n",
            "    return self._sslobj.read(len, buffer)\n",
            "socket.timeout: The read operation timed out\n",
            "\n",
            "During handling of the above exception, another exception occurred:\n",
            "\n",
            "Traceback (most recent call last):\n",
            "  File \"/usr/local/lib/python3.7/dist-packages/geopy/extra/rate_limiter.py\", line 130, in __call__\n",
            "    return self.func(*args, **kwargs)\n",
            "  File \"/usr/local/lib/python3.7/dist-packages/geopy/geocoders/osm.py\", line 307, in geocode\n",
            "    self._call_geocoder(url, timeout=timeout), exactly_one\n",
            "  File \"/usr/local/lib/python3.7/dist-packages/geopy/geocoders/base.py\", line 371, in _call_geocoder\n",
            "    raise GeocoderTimedOut('Service timed out')\n",
            "geopy.exc.GeocoderTimedOut: Service timed out\n",
            "RateLimiter swallowed an error after 2 retries. Called with (*('MUANA, 214,SAO PAULO - SP - BRAZIL',), **{}).\n",
            "Traceback (most recent call last):\n",
            "  File \"/usr/local/lib/python3.7/dist-packages/geopy/geocoders/base.py\", line 344, in _call_geocoder\n",
            "    page = requester(req, timeout=timeout, **kwargs)\n",
            "  File \"/usr/lib/python3.7/urllib/request.py\", line 525, in open\n",
            "    response = self._open(req, data)\n",
            "  File \"/usr/lib/python3.7/urllib/request.py\", line 543, in _open\n",
            "    '_open', req)\n",
            "  File \"/usr/lib/python3.7/urllib/request.py\", line 503, in _call_chain\n",
            "    result = func(*args)\n",
            "  File \"/usr/lib/python3.7/urllib/request.py\", line 1393, in https_open\n",
            "    context=self._context, check_hostname=self._check_hostname)\n",
            "  File \"/usr/lib/python3.7/urllib/request.py\", line 1353, in do_open\n",
            "    r = h.getresponse()\n",
            "  File \"/usr/lib/python3.7/http/client.py\", line 1373, in getresponse\n",
            "    response.begin()\n",
            "  File \"/usr/lib/python3.7/http/client.py\", line 319, in begin\n",
            "    version, status, reason = self._read_status()\n",
            "  File \"/usr/lib/python3.7/http/client.py\", line 280, in _read_status\n",
            "    line = str(self.fp.readline(_MAXLINE + 1), \"iso-8859-1\")\n",
            "  File \"/usr/lib/python3.7/socket.py\", line 589, in readinto\n",
            "    return self._sock.recv_into(b)\n",
            "  File \"/usr/lib/python3.7/ssl.py\", line 1071, in recv_into\n",
            "    return self.read(nbytes, buffer)\n",
            "  File \"/usr/lib/python3.7/ssl.py\", line 929, in read\n",
            "    return self._sslobj.read(len, buffer)\n",
            "socket.timeout: The read operation timed out\n",
            "\n",
            "During handling of the above exception, another exception occurred:\n",
            "\n",
            "Traceback (most recent call last):\n",
            "  File \"/usr/local/lib/python3.7/dist-packages/geopy/extra/rate_limiter.py\", line 130, in __call__\n",
            "    return self.func(*args, **kwargs)\n",
            "  File \"/usr/local/lib/python3.7/dist-packages/geopy/geocoders/osm.py\", line 307, in geocode\n",
            "    self._call_geocoder(url, timeout=timeout), exactly_one\n",
            "  File \"/usr/local/lib/python3.7/dist-packages/geopy/geocoders/base.py\", line 371, in _call_geocoder\n",
            "    raise GeocoderTimedOut('Service timed out')\n",
            "geopy.exc.GeocoderTimedOut: Service timed out\n",
            "RateLimiter caught an error, retrying (0/2 tries). Called with (*('SOL R, 45,SAO PAULO - SP - BRAZIL',), **{}).\n",
            "Traceback (most recent call last):\n",
            "  File \"/usr/local/lib/python3.7/dist-packages/geopy/geocoders/base.py\", line 344, in _call_geocoder\n",
            "    page = requester(req, timeout=timeout, **kwargs)\n",
            "  File \"/usr/lib/python3.7/urllib/request.py\", line 525, in open\n",
            "    response = self._open(req, data)\n",
            "  File \"/usr/lib/python3.7/urllib/request.py\", line 543, in _open\n",
            "    '_open', req)\n",
            "  File \"/usr/lib/python3.7/urllib/request.py\", line 503, in _call_chain\n",
            "    result = func(*args)\n",
            "  File \"/usr/lib/python3.7/urllib/request.py\", line 1393, in https_open\n",
            "    context=self._context, check_hostname=self._check_hostname)\n",
            "  File \"/usr/lib/python3.7/urllib/request.py\", line 1353, in do_open\n",
            "    r = h.getresponse()\n",
            "  File \"/usr/lib/python3.7/http/client.py\", line 1373, in getresponse\n",
            "    response.begin()\n",
            "  File \"/usr/lib/python3.7/http/client.py\", line 319, in begin\n",
            "    version, status, reason = self._read_status()\n",
            "  File \"/usr/lib/python3.7/http/client.py\", line 280, in _read_status\n",
            "    line = str(self.fp.readline(_MAXLINE + 1), \"iso-8859-1\")\n",
            "  File \"/usr/lib/python3.7/socket.py\", line 589, in readinto\n",
            "    return self._sock.recv_into(b)\n",
            "  File \"/usr/lib/python3.7/ssl.py\", line 1071, in recv_into\n",
            "    return self.read(nbytes, buffer)\n",
            "  File \"/usr/lib/python3.7/ssl.py\", line 929, in read\n",
            "    return self._sslobj.read(len, buffer)\n",
            "socket.timeout: The read operation timed out\n",
            "\n",
            "During handling of the above exception, another exception occurred:\n",
            "\n",
            "Traceback (most recent call last):\n",
            "  File \"/usr/local/lib/python3.7/dist-packages/geopy/extra/rate_limiter.py\", line 130, in __call__\n",
            "    return self.func(*args, **kwargs)\n",
            "  File \"/usr/local/lib/python3.7/dist-packages/geopy/geocoders/osm.py\", line 307, in geocode\n",
            "    self._call_geocoder(url, timeout=timeout), exactly_one\n",
            "  File \"/usr/local/lib/python3.7/dist-packages/geopy/geocoders/base.py\", line 371, in _call_geocoder\n",
            "    raise GeocoderTimedOut('Service timed out')\n",
            "geopy.exc.GeocoderTimedOut: Service timed out\n",
            "RateLimiter caught an error, retrying (1/2 tries). Called with (*('SOL R, 45,SAO PAULO - SP - BRAZIL',), **{}).\n",
            "Traceback (most recent call last):\n",
            "  File \"/usr/local/lib/python3.7/dist-packages/geopy/geocoders/base.py\", line 344, in _call_geocoder\n",
            "    page = requester(req, timeout=timeout, **kwargs)\n",
            "  File \"/usr/lib/python3.7/urllib/request.py\", line 525, in open\n",
            "    response = self._open(req, data)\n",
            "  File \"/usr/lib/python3.7/urllib/request.py\", line 543, in _open\n",
            "    '_open', req)\n",
            "  File \"/usr/lib/python3.7/urllib/request.py\", line 503, in _call_chain\n",
            "    result = func(*args)\n",
            "  File \"/usr/lib/python3.7/urllib/request.py\", line 1393, in https_open\n",
            "    context=self._context, check_hostname=self._check_hostname)\n",
            "  File \"/usr/lib/python3.7/urllib/request.py\", line 1353, in do_open\n",
            "    r = h.getresponse()\n",
            "  File \"/usr/lib/python3.7/http/client.py\", line 1373, in getresponse\n",
            "    response.begin()\n",
            "  File \"/usr/lib/python3.7/http/client.py\", line 319, in begin\n",
            "    version, status, reason = self._read_status()\n",
            "  File \"/usr/lib/python3.7/http/client.py\", line 280, in _read_status\n",
            "    line = str(self.fp.readline(_MAXLINE + 1), \"iso-8859-1\")\n",
            "  File \"/usr/lib/python3.7/socket.py\", line 589, in readinto\n",
            "    return self._sock.recv_into(b)\n",
            "  File \"/usr/lib/python3.7/ssl.py\", line 1071, in recv_into\n",
            "    return self.read(nbytes, buffer)\n",
            "  File \"/usr/lib/python3.7/ssl.py\", line 929, in read\n",
            "    return self._sslobj.read(len, buffer)\n",
            "socket.timeout: The read operation timed out\n",
            "\n",
            "During handling of the above exception, another exception occurred:\n",
            "\n",
            "Traceback (most recent call last):\n",
            "  File \"/usr/local/lib/python3.7/dist-packages/geopy/extra/rate_limiter.py\", line 130, in __call__\n",
            "    return self.func(*args, **kwargs)\n",
            "  File \"/usr/local/lib/python3.7/dist-packages/geopy/geocoders/osm.py\", line 307, in geocode\n",
            "    self._call_geocoder(url, timeout=timeout), exactly_one\n",
            "  File \"/usr/local/lib/python3.7/dist-packages/geopy/geocoders/base.py\", line 371, in _call_geocoder\n",
            "    raise GeocoderTimedOut('Service timed out')\n",
            "geopy.exc.GeocoderTimedOut: Service timed out\n",
            "RateLimiter swallowed an error after 2 retries. Called with (*('SOL R, 45,SAO PAULO - SP - BRAZIL',), **{}).\n",
            "Traceback (most recent call last):\n",
            "  File \"/usr/local/lib/python3.7/dist-packages/geopy/geocoders/base.py\", line 344, in _call_geocoder\n",
            "    page = requester(req, timeout=timeout, **kwargs)\n",
            "  File \"/usr/lib/python3.7/urllib/request.py\", line 525, in open\n",
            "    response = self._open(req, data)\n",
            "  File \"/usr/lib/python3.7/urllib/request.py\", line 543, in _open\n",
            "    '_open', req)\n",
            "  File \"/usr/lib/python3.7/urllib/request.py\", line 503, in _call_chain\n",
            "    result = func(*args)\n",
            "  File \"/usr/lib/python3.7/urllib/request.py\", line 1393, in https_open\n",
            "    context=self._context, check_hostname=self._check_hostname)\n",
            "  File \"/usr/lib/python3.7/urllib/request.py\", line 1353, in do_open\n",
            "    r = h.getresponse()\n",
            "  File \"/usr/lib/python3.7/http/client.py\", line 1373, in getresponse\n",
            "    response.begin()\n",
            "  File \"/usr/lib/python3.7/http/client.py\", line 319, in begin\n",
            "    version, status, reason = self._read_status()\n",
            "  File \"/usr/lib/python3.7/http/client.py\", line 280, in _read_status\n",
            "    line = str(self.fp.readline(_MAXLINE + 1), \"iso-8859-1\")\n",
            "  File \"/usr/lib/python3.7/socket.py\", line 589, in readinto\n",
            "    return self._sock.recv_into(b)\n",
            "  File \"/usr/lib/python3.7/ssl.py\", line 1071, in recv_into\n",
            "    return self.read(nbytes, buffer)\n",
            "  File \"/usr/lib/python3.7/ssl.py\", line 929, in read\n",
            "    return self._sslobj.read(len, buffer)\n",
            "socket.timeout: The read operation timed out\n",
            "\n",
            "During handling of the above exception, another exception occurred:\n",
            "\n",
            "Traceback (most recent call last):\n",
            "  File \"/usr/local/lib/python3.7/dist-packages/geopy/extra/rate_limiter.py\", line 130, in __call__\n",
            "    return self.func(*args, **kwargs)\n",
            "  File \"/usr/local/lib/python3.7/dist-packages/geopy/geocoders/osm.py\", line 307, in geocode\n",
            "    self._call_geocoder(url, timeout=timeout), exactly_one\n",
            "  File \"/usr/local/lib/python3.7/dist-packages/geopy/geocoders/base.py\", line 371, in _call_geocoder\n",
            "    raise GeocoderTimedOut('Service timed out')\n",
            "geopy.exc.GeocoderTimedOut: Service timed out\n",
            "RateLimiter caught an error, retrying (0/2 tries). Called with (*('TAIOBEIRAS, 125,SAO PAULO - SP - BRAZIL',), **{}).\n",
            "Traceback (most recent call last):\n",
            "  File \"/usr/local/lib/python3.7/dist-packages/geopy/geocoders/base.py\", line 344, in _call_geocoder\n",
            "    page = requester(req, timeout=timeout, **kwargs)\n",
            "  File \"/usr/lib/python3.7/urllib/request.py\", line 525, in open\n",
            "    response = self._open(req, data)\n",
            "  File \"/usr/lib/python3.7/urllib/request.py\", line 543, in _open\n",
            "    '_open', req)\n",
            "  File \"/usr/lib/python3.7/urllib/request.py\", line 503, in _call_chain\n",
            "    result = func(*args)\n",
            "  File \"/usr/lib/python3.7/urllib/request.py\", line 1393, in https_open\n",
            "    context=self._context, check_hostname=self._check_hostname)\n",
            "  File \"/usr/lib/python3.7/urllib/request.py\", line 1353, in do_open\n",
            "    r = h.getresponse()\n",
            "  File \"/usr/lib/python3.7/http/client.py\", line 1373, in getresponse\n",
            "    response.begin()\n",
            "  File \"/usr/lib/python3.7/http/client.py\", line 319, in begin\n",
            "    version, status, reason = self._read_status()\n",
            "  File \"/usr/lib/python3.7/http/client.py\", line 280, in _read_status\n",
            "    line = str(self.fp.readline(_MAXLINE + 1), \"iso-8859-1\")\n",
            "  File \"/usr/lib/python3.7/socket.py\", line 589, in readinto\n",
            "    return self._sock.recv_into(b)\n",
            "  File \"/usr/lib/python3.7/ssl.py\", line 1071, in recv_into\n",
            "    return self.read(nbytes, buffer)\n",
            "  File \"/usr/lib/python3.7/ssl.py\", line 929, in read\n",
            "    return self._sslobj.read(len, buffer)\n",
            "socket.timeout: The read operation timed out\n",
            "\n",
            "During handling of the above exception, another exception occurred:\n",
            "\n",
            "Traceback (most recent call last):\n",
            "  File \"/usr/local/lib/python3.7/dist-packages/geopy/extra/rate_limiter.py\", line 130, in __call__\n",
            "    return self.func(*args, **kwargs)\n",
            "  File \"/usr/local/lib/python3.7/dist-packages/geopy/geocoders/osm.py\", line 307, in geocode\n",
            "    self._call_geocoder(url, timeout=timeout), exactly_one\n",
            "  File \"/usr/local/lib/python3.7/dist-packages/geopy/geocoders/base.py\", line 371, in _call_geocoder\n",
            "    raise GeocoderTimedOut('Service timed out')\n",
            "geopy.exc.GeocoderTimedOut: Service timed out\n",
            "RateLimiter caught an error, retrying (1/2 tries). Called with (*('TAIOBEIRAS, 125,SAO PAULO - SP - BRAZIL',), **{}).\n",
            "Traceback (most recent call last):\n",
            "  File \"/usr/local/lib/python3.7/dist-packages/geopy/geocoders/base.py\", line 344, in _call_geocoder\n",
            "    page = requester(req, timeout=timeout, **kwargs)\n",
            "  File \"/usr/lib/python3.7/urllib/request.py\", line 525, in open\n",
            "    response = self._open(req, data)\n",
            "  File \"/usr/lib/python3.7/urllib/request.py\", line 543, in _open\n",
            "    '_open', req)\n",
            "  File \"/usr/lib/python3.7/urllib/request.py\", line 503, in _call_chain\n",
            "    result = func(*args)\n",
            "  File \"/usr/lib/python3.7/urllib/request.py\", line 1393, in https_open\n",
            "    context=self._context, check_hostname=self._check_hostname)\n",
            "  File \"/usr/lib/python3.7/urllib/request.py\", line 1353, in do_open\n",
            "    r = h.getresponse()\n",
            "  File \"/usr/lib/python3.7/http/client.py\", line 1373, in getresponse\n",
            "    response.begin()\n",
            "  File \"/usr/lib/python3.7/http/client.py\", line 319, in begin\n",
            "    version, status, reason = self._read_status()\n",
            "  File \"/usr/lib/python3.7/http/client.py\", line 280, in _read_status\n",
            "    line = str(self.fp.readline(_MAXLINE + 1), \"iso-8859-1\")\n",
            "  File \"/usr/lib/python3.7/socket.py\", line 589, in readinto\n",
            "    return self._sock.recv_into(b)\n",
            "  File \"/usr/lib/python3.7/ssl.py\", line 1071, in recv_into\n",
            "    return self.read(nbytes, buffer)\n",
            "  File \"/usr/lib/python3.7/ssl.py\", line 929, in read\n",
            "    return self._sslobj.read(len, buffer)\n",
            "socket.timeout: The read operation timed out\n",
            "\n",
            "During handling of the above exception, another exception occurred:\n",
            "\n",
            "Traceback (most recent call last):\n",
            "  File \"/usr/local/lib/python3.7/dist-packages/geopy/extra/rate_limiter.py\", line 130, in __call__\n",
            "    return self.func(*args, **kwargs)\n",
            "  File \"/usr/local/lib/python3.7/dist-packages/geopy/geocoders/osm.py\", line 307, in geocode\n",
            "    self._call_geocoder(url, timeout=timeout), exactly_one\n",
            "  File \"/usr/local/lib/python3.7/dist-packages/geopy/geocoders/base.py\", line 371, in _call_geocoder\n",
            "    raise GeocoderTimedOut('Service timed out')\n",
            "geopy.exc.GeocoderTimedOut: Service timed out\n",
            "RateLimiter swallowed an error after 2 retries. Called with (*('TAIOBEIRAS, 125,SAO PAULO - SP - BRAZIL',), **{}).\n",
            "Traceback (most recent call last):\n",
            "  File \"/usr/local/lib/python3.7/dist-packages/geopy/geocoders/base.py\", line 344, in _call_geocoder\n",
            "    page = requester(req, timeout=timeout, **kwargs)\n",
            "  File \"/usr/lib/python3.7/urllib/request.py\", line 525, in open\n",
            "    response = self._open(req, data)\n",
            "  File \"/usr/lib/python3.7/urllib/request.py\", line 543, in _open\n",
            "    '_open', req)\n",
            "  File \"/usr/lib/python3.7/urllib/request.py\", line 503, in _call_chain\n",
            "    result = func(*args)\n",
            "  File \"/usr/lib/python3.7/urllib/request.py\", line 1393, in https_open\n",
            "    context=self._context, check_hostname=self._check_hostname)\n",
            "  File \"/usr/lib/python3.7/urllib/request.py\", line 1353, in do_open\n",
            "    r = h.getresponse()\n",
            "  File \"/usr/lib/python3.7/http/client.py\", line 1373, in getresponse\n",
            "    response.begin()\n",
            "  File \"/usr/lib/python3.7/http/client.py\", line 319, in begin\n",
            "    version, status, reason = self._read_status()\n",
            "  File \"/usr/lib/python3.7/http/client.py\", line 280, in _read_status\n",
            "    line = str(self.fp.readline(_MAXLINE + 1), \"iso-8859-1\")\n",
            "  File \"/usr/lib/python3.7/socket.py\", line 589, in readinto\n",
            "    return self._sock.recv_into(b)\n",
            "  File \"/usr/lib/python3.7/ssl.py\", line 1071, in recv_into\n",
            "    return self.read(nbytes, buffer)\n",
            "  File \"/usr/lib/python3.7/ssl.py\", line 929, in read\n",
            "    return self._sslobj.read(len, buffer)\n",
            "socket.timeout: The read operation timed out\n",
            "\n",
            "During handling of the above exception, another exception occurred:\n",
            "\n",
            "Traceback (most recent call last):\n",
            "  File \"/usr/local/lib/python3.7/dist-packages/geopy/extra/rate_limiter.py\", line 130, in __call__\n",
            "    return self.func(*args, **kwargs)\n",
            "  File \"/usr/local/lib/python3.7/dist-packages/geopy/geocoders/osm.py\", line 307, in geocode\n",
            "    self._call_geocoder(url, timeout=timeout), exactly_one\n",
            "  File \"/usr/local/lib/python3.7/dist-packages/geopy/geocoders/base.py\", line 371, in _call_geocoder\n",
            "    raise GeocoderTimedOut('Service timed out')\n",
            "geopy.exc.GeocoderTimedOut: Service timed out\n"
          ]
        }
      ],
      "source": [
        "#import pycep_correios\n",
        "#from pycep_correios import get_address_from_cep, WebService\n",
        "from geopy.geocoders import Nominatim\n",
        "from geopy.extra.rate_limiter import RateLimiter\n",
        "import pandas as pd\n",
        "\n",
        "\n",
        "# endereco = pycep_correios.get_address_from_cep('03987-110', webservice=WebService.APICEP)\n",
        "#print(endereco)\n",
        "\n",
        "\n",
        "UBS = pd.read_csv('/content/drive/MyDrive/info_vacinas/postos_de_saude_SP.csv', delimiter=\";\")\n",
        "print(UBS.head())\n",
        "geolocator = Nominatim(user_agent=\"test_app\")\n",
        "# location = geolocator.geocode(endereco['logradouro'] + \", \" + endereco['cidade'])\n",
        "geocode = RateLimiter(geolocator.geocode, min_delay_seconds=1.5)\n",
        "# location = geolocator.geocode('Av 25 de agosto, Cruzeiro do Sul, AC, brazil')\n",
        "#print(location.latitude, location.longitude)\n",
        "UBS['END_GEO'] = UBS['END_COMPLETO'].apply(geocode)"
      ]
    },
    {
      "cell_type": "code",
      "source": [
        "location = geolocator.geocode('RUA NOVE DE JULHO, 841,ADAMANTINA - SP - BRAZIL')\n",
        "print(location)"
      ],
      "metadata": {
        "colab": {
          "base_uri": "https://localhost:8080/"
        },
        "id": "KcxY-CL2VBUl",
        "outputId": "e223602d-0396-47be-b7fa-08c83aa7fe92"
      },
      "execution_count": null,
      "outputs": [
        {
          "output_type": "stream",
          "name": "stdout",
          "text": [
            "None\n"
          ]
        }
      ]
    },
    {
      "cell_type": "code",
      "source": [
        "UBS['point'] = UBS['END_GEO'].apply(lambda loc: tuple(loc.point) if loc else None)"
      ],
      "metadata": {
        "id": "93qgeBB7StiS"
      },
      "execution_count": null,
      "outputs": []
    },
    {
      "cell_type": "code",
      "source": [
        "UBS.to_csv(\"/content/drive/MyDrive/info_vacinas/postos_resultSP.csv\", encoding = 'utf-8')"
      ],
      "metadata": {
        "id": "pGy4bJG6TT7K"
      },
      "execution_count": null,
      "outputs": []
    },
    {
      "cell_type": "code",
      "source": [
        "pip install geopy"
      ],
      "metadata": {
        "colab": {
          "base_uri": "https://localhost:8080/"
        },
        "id": "THR4DzJqA3Wl",
        "outputId": "e8c2c320-ad77-4676-cf51-02dfe0e20249"
      },
      "execution_count": null,
      "outputs": [
        {
          "output_type": "stream",
          "name": "stdout",
          "text": [
            "Looking in indexes: https://pypi.org/simple, https://us-python.pkg.dev/colab-wheels/public/simple/\n",
            "Requirement already satisfied: geopy in /usr/local/lib/python3.7/dist-packages (1.17.0)\n",
            "Requirement already satisfied: geographiclib<2,>=1.49 in /usr/local/lib/python3.7/dist-packages (from geopy) (1.52)\n"
          ]
        }
      ]
    },
    {
      "cell_type": "code",
      "source": [
        "from geopy.geocoders import TomTom\n",
        "from geopy.extra.rate_limiter import RateLimiter\n",
        "import pandas as pd\n",
        "\n",
        "df = pd.read_csv('/content/drive/MyDrive/info_vacinas/postos_n_enc.csv', delimiter=\";\")\n",
        "#print(UBS.head())\n",
        "geolocator = TomTom(api_key='wvuAFmBut64DLjQqey19XtfuMXZilzbj', user_agent=\"None\")\n",
        "# location = geolocator.geocode(endereco['logradouro'] + \", \" + endereco['cidade'])\n",
        "geocode = RateLimiter(geolocator.geocode, min_delay_seconds=1)\n",
        "# location = geolocator.geocode('Av 25 de agosto, Cruzeiro do Sul, AC, brazil')\n",
        "#print(location.latitude, location.longitude)\n",
        "df['END_GEO'] = df['END_COMPLETO'].apply(geocode)"
      ],
      "metadata": {
        "colab": {
          "base_uri": "https://localhost:8080/"
        },
        "id": "5D7lEHmm_N__",
        "outputId": "877b60e0-362d-4bb9-ce49-4f6c55720940"
      },
      "execution_count": null,
      "outputs": [
        {
          "output_type": "stream",
          "name": "stderr",
          "text": [
            "RateLimiter caught an error, retrying (0/2 tries). Called with (*('PC JOSE ROBERTO M TEIXEIRA, 47,SAO SEBASTIAO DA GRAMA - SP - BRAZIL',), **{}).\n",
            "Traceback (most recent call last):\n",
            "  File \"/usr/local/lib/python3.7/dist-packages/geopy/geocoders/base.py\", line 344, in _call_geocoder\n",
            "    page = requester(req, timeout=timeout, **kwargs)\n",
            "  File \"/usr/lib/python3.7/urllib/request.py\", line 525, in open\n",
            "    response = self._open(req, data)\n",
            "  File \"/usr/lib/python3.7/urllib/request.py\", line 543, in _open\n",
            "    '_open', req)\n",
            "  File \"/usr/lib/python3.7/urllib/request.py\", line 503, in _call_chain\n",
            "    result = func(*args)\n",
            "  File \"/usr/lib/python3.7/urllib/request.py\", line 1393, in https_open\n",
            "    context=self._context, check_hostname=self._check_hostname)\n",
            "  File \"/usr/lib/python3.7/urllib/request.py\", line 1353, in do_open\n",
            "    r = h.getresponse()\n",
            "  File \"/usr/lib/python3.7/http/client.py\", line 1373, in getresponse\n",
            "    response.begin()\n",
            "  File \"/usr/lib/python3.7/http/client.py\", line 319, in begin\n",
            "    version, status, reason = self._read_status()\n",
            "  File \"/usr/lib/python3.7/http/client.py\", line 280, in _read_status\n",
            "    line = str(self.fp.readline(_MAXLINE + 1), \"iso-8859-1\")\n",
            "  File \"/usr/lib/python3.7/socket.py\", line 589, in readinto\n",
            "    return self._sock.recv_into(b)\n",
            "  File \"/usr/lib/python3.7/ssl.py\", line 1071, in recv_into\n",
            "    return self.read(nbytes, buffer)\n",
            "  File \"/usr/lib/python3.7/ssl.py\", line 929, in read\n",
            "    return self._sslobj.read(len, buffer)\n",
            "socket.timeout: The read operation timed out\n",
            "\n",
            "During handling of the above exception, another exception occurred:\n",
            "\n",
            "Traceback (most recent call last):\n",
            "  File \"/usr/local/lib/python3.7/dist-packages/geopy/extra/rate_limiter.py\", line 130, in __call__\n",
            "    return self.func(*args, **kwargs)\n",
            "  File \"/usr/local/lib/python3.7/dist-packages/geopy/geocoders/tomtom.py\", line 125, in geocode\n",
            "    self._call_geocoder(url, timeout=timeout), exactly_one\n",
            "  File \"/usr/local/lib/python3.7/dist-packages/geopy/geocoders/base.py\", line 371, in _call_geocoder\n",
            "    raise GeocoderTimedOut('Service timed out')\n",
            "geopy.exc.GeocoderTimedOut: Service timed out\n"
          ]
        }
      ]
    },
    {
      "cell_type": "code",
      "source": [
        "df['point'] = df['END_GEO'].apply(lambda loc: tuple(loc.point) if loc else None)\n",
        "df.to_csv(\"/content/drive/MyDrive/info_vacinas/postos_SPTomTom.csv\", encoding = 'utf-8')"
      ],
      "metadata": {
        "id": "3LZ6QIfEMl-F"
      },
      "execution_count": null,
      "outputs": []
    },
    {
      "cell_type": "code",
      "source": [
        "df.to_excel(\"/content/drive/MyDrive/info_vacinas/postos_SPTomTom.xlsx\", encoding = 'utf-8')"
      ],
      "metadata": {
        "id": "-zVc4ZJXNTuZ"
      },
      "execution_count": null,
      "outputs": []
    }
  ],
  "metadata": {
    "colab": {
      "provenance": []
    },
    "kernelspec": {
      "display_name": "Python 3",
      "name": "python3"
    },
    "language_info": {
      "name": "python"
    }
  },
  "nbformat": 4,
  "nbformat_minor": 0
}